<sdf version="1.7">
  <world name="sim_world">
    <physics name="10ms" type="ode">
      <max_step_size>0.01</max_step_size>
      <real_time_factor>1.0</real_time_factor>
    </physics>
    <plugin filename="gz-sim-physics-system" name="gz::sim::systems::Physics">
    </plugin>
    <plugin filename="gz-sim-user-commands-system" name="gz::sim::systems::UserCommands">
    </plugin>
    <plugin filename="gz-sim-scene-broadcaster-system" name="gz::sim::systems::SceneBroadcaster">
    </plugin>
    <plugin filename="libdoor.so" name="door">
    </plugin>
    <plugin filename="liblift.so" name="lift">
    </plugin>
    <scene>
      <ambient>1 1 1</ambient>
      <background>0.8 0.8 0.8</background>
      <grid>false</grid>
    </scene>
    <gui fullscreen="0">
      <window>
        <width>1000</width>
        <height>845</height>
        <style material_theme="Light" material_primary="DeepOrange" material_accent="LightBlue" toolbar_color_light="#f3f3f3" toolbar_text_color_light="#111111" toolbar_color_dark="#414141" toolbar_text_color_dark="#f3f3f3" plugin_toolbar_color_light="#bbdefb" plugin_toolbar_text_color_light="#111111" plugin_toolbar_color_dark="#607d8b" plugin_toolbar_text_color_dark="#eeeeee" />
        <menus>
          <drawer default="false">
          </drawer>
        </menus>
      </window>
      <plugin filename="MinimalScene" name="3D View">
        <gz-gui>
          <title>3D View</title>
          <property type="bool" key="showTitleBar">false</property>
          <property type="string" key="state">docked</property>
        </gz-gui>
        <engine>ogre2</engine>
        <scene>scene</scene>
        <ambient_light>0.4 0.4 0.4</ambient_light>
        <background_color>0.8 0.8 0.8</background_color>
        <camera_pose>16.034441915685896 -43.27382081888868 10 0 0.6 1.57</camera_pose>
      </plugin>
      <plugin filename="EntityContextMenuPlugin" name="Entity context menu">
        <gz-gui>
          <property key="state" type="string">floating</property>
          <property key="width" type="double">5</property>
          <property key="height" type="double">5</property>
          <property key="showTitleBar" type="bool">false</property>
        </gz-gui>
      </plugin>
      <plugin filename="GzSceneManager" name="Scene Manager">
        <gz-gui>
          <property key="resizable" type="bool">false</property>
          <property key="width" type="double">5</property>
          <property key="height" type="double">5</property>
          <property key="state" type="string">floating</property>
          <property key="showTitleBar" type="bool">false</property>
        </gz-gui>
      </plugin>
      <plugin filename="InteractiveViewControl" name="Interactive view control">
        <gz-gui>
          <property key="resizable" type="bool">false</property>
          <property key="width" type="double">5</property>
          <property key="height" type="double">5</property>
          <property key="state" type="string">floating</property>
          <property key="showTitleBar" type="bool">false</property>
        </gz-gui>
      </plugin>
      <plugin filename="CameraTracking" name="Camera Tracking">
        <gz-gui>
          <property key="resizable" type="bool">false</property>
          <property key="width" type="double">5</property>
          <property key="height" type="double">5</property>
          <property key="state" type="string">floating</property>
          <property key="showTitleBar" type="bool">false</property>
        </gz-gui>
      </plugin>
      <plugin filename="MarkerManager" name="Marker manager">
        <gz-gui>
          <property key="resizable" type="bool">false</property>
          <property key="width" type="double">5</property>
          <property key="height" type="double">5</property>
          <property key="state" type="string">floating</property>
          <property key="showTitleBar" type="bool">false</property>
        </gz-gui>
      </plugin>
      <plugin filename="SelectEntities" name="Select Entities">
        <gz-gui>
          <property key="resizable" type="bool">false</property>
          <property key="width" type="double">5</property>
          <property key="height" type="double">5</property>
          <property key="state" type="string">floating</property>
          <property key="showTitleBar" type="bool">false</property>
        </gz-gui>
      </plugin>
      <plugin filename="Spawn" name="Spawn Entities">
        <gz-gui>
          <property key="resizable" type="bool">false</property>
          <property key="width" type="double">5</property>
          <property key="height" type="double">5</property>
          <property key="state" type="string">floating</property>
          <property key="showTitleBar" type="bool">false</property>
        </gz-gui>
      </plugin>
      <plugin filename="VisualizationCapabilities" name="Visualization Capabilities">
        <gz-gui>
          <property key="resizable" type="bool">false</property>
          <property key="width" type="double">5</property>
          <property key="height" type="double">5</property>
          <property key="state" type="string">floating</property>
          <property key="showTitleBar" type="bool">false</property>
        </gz-gui>
      </plugin>
      <plugin filename="WorldControl" name="World control">
        <gz-gui>
          <title>World control</title>
          <property type="bool" key="showTitleBar">false</property>
          <property type="bool" key="resizable">false</property>
          <property type="double" key="height">72</property>
          <property type="double" key="z">1</property>
          <property type="string" key="state">floating</property>
          <anchors target="3D View">
            <line own="left" target="left" />
            <line own="bottom" target="bottom" />
          </anchors>
        </gz-gui>
        <play_pause>true</play_pause>
        <step>true</step>
        <start_paused>true</start_paused>
        <use_event>true</use_event>
      </plugin>
      <plugin filename="WorldStats" name="World stats">
        <gz-gui>
          <title>World stats</title>
          <property type="bool" key="showTitleBar">false</property>
          <property type="bool" key="resizable">false</property>
          <property type="double" key="height">110</property>
          <property type="double" key="width">290</property>
          <property type="double" key="z">1</property>
          <property type="string" key="state">floating</property>
          <anchors target="3D View">
            <line own="right" target="right" />
            <line own="bottom" target="bottom" />
          </anchors>
        </gz-gui>
        <sim_time>true</sim_time>
        <real_time>true</real_time>
        <real_time_factor>true</real_time_factor>
        <iterations>true</iterations>
      </plugin>
      <plugin filename="Shapes" name="Shapes">
        <gz-gui>
          <property key="resizable" type="bool">false</property>
          <property key="x" type="double">0</property>
          <property key="y" type="double">0</property>
          <property key="width" type="double">250</property>
          <property key="height" type="double">50</property>
          <property key="state" type="string">floating</property>
          <property key="showTitleBar" type="bool">false</property>
          <property key="cardBackground" type="string">#666666</property>
        </gz-gui>
      </plugin>
      <plugin filename="Lights" name="Lights">
        <gz-gui>
          <property key="resizable" type="bool">false</property>
          <property key="x" type="double">250</property>
          <property key="y" type="double">0</property>
          <property key="width" type="double">150</property>
          <property key="height" type="double">50</property>
          <property key="state" type="string">floating</property>
          <property key="showTitleBar" type="bool">false</property>
          <property key="cardBackground" type="string">#666666</property>
        </gz-gui>
      </plugin>
      <plugin filename="TransformControl" name="Transform control">
        <gz-gui>
          <property key="resizable" type="bool">false</property>
          <property key="x" type="double">0</property>
          <property key="y" type="double">50</property>
          <property key="width" type="double">250</property>
          <property key="height" type="double">50</property>
          <property key="state" type="string">floating</property>
          <property key="showTitleBar" type="bool">false</property>
          <property key="cardBackground" type="string">#777777</property>
        </gz-gui>
      </plugin>
      <plugin filename="Screenshot" name="Screenshot">
        <gz-gui>
          <property key="resizable" type="bool">false</property>
          <property key="x" type="double">250</property>
          <property key="y" type="double">50</property>
          <property key="width" type="double">50</property>
          <property key="height" type="double">50</property>
          <property key="state" type="string">floating</property>
          <property key="showTitleBar" type="bool">false</property>
          <property key="cardBackground" type="string">#777777</property>
        </gz-gui>
      </plugin>
      <plugin filename="CopyPaste" name="CopyPaste">
        <gz-gui>
          <property key="resizable" type="bool">false</property>
          <property key="x" type="double">300</property>
          <property key="y" type="double">50</property>
          <property key="width" type="double">100</property>
          <property key="height" type="double">50</property>
          <property key="state" type="string">floating</property>
          <property key="showTitleBar" type="bool">false</property>
          <property key="cardBackground" type="string">#777777</property>
        </gz-gui>
      </plugin>
      <plugin filename="ComponentInspector" name="Component inspector">
        <gz-gui>
          <property type="bool" key="showTitleBar">false</property>
          <property type="string" key="state">docked</property>
        </gz-gui>
      </plugin>
      <plugin filename="EntityTree" name="Entity tree">
        <gz-gui>
          <property type="bool" key="showTitleBar">false</property>
          <property type="string" key="state">docked</property>
        </gz-gui>
      </plugin>
      <plugin filename="toggle_charging" name="toggle_charging" />
      <plugin name="toggle_floors" filename="toggle_floors">
        <floor name="L1" model_name="kioto_L1">
          <model name="OpenRobotics/AdjTable" />
          <model name="OpenRobotics/AdjTable_2" />
          <model name="OpenRobotics/AdjTable_3" />
          <model name="OpenRobotics/AdjTable_4" />
          <model name="OpenRobotics/AdjTable_5" />
          <model name="OpenRobotics/AdjTable_6" />
          <model name="OpenRobotics/AdjTable_7" />
          <model name="OpenRobotics/AdjTable_8" />
          <model name="OpenRobotics/AdjTable_9" />
          <model name="OpenRobotics/AdjTable_10" />
          <model name="OpenRobotics/AdjTable_11" />
          <model name="OpenRobotics/AdjTable_12" />
          <model name="OpenRobotics/OfficeChairGrey" />
          <model name="OpenRobotics/OfficeChairGrey_2" />
          <model name="OpenRobotics/OfficeChairGrey_3" />
          <model name="OpenRobotics/OfficeChairGrey_4" />
          <model name="OpenRobotics/OfficeChairGrey_5" />
          <model name="OpenRobotics/OfficeChairGrey_6" />
          <model name="OpenRobotics/OfficeChairGrey_7" />
          <model name="OpenRobotics/OfficeChairGrey_8" />
          <model name="OpenRobotics/OfficeChairGrey_9" />
          <model name="OpenRobotics/OfficeChairGrey_10" />
          <model name="OpenRobotics/OfficeChairGrey_11" />
          <model name="OpenRobotics/OfficeChairGrey_12" />
          <model name="OpenRobotics/OfficeChairGrey_13" />
          <model name="OpenRobotics/OfficeChairGrey_14" />
          <model name="OpenRobotics/OfficeChairGrey_15" />
          <model name="OpenRobotics/OfficeChairGrey_16" />
          <model name="OpenRobotics/OfficeChairGrey_17" />
          <model name="OpenRobotics/OfficeChairGrey_18" />
          <model name="OpenRobotics/OfficeChairGrey_19" />
          <model name="OpenRobotics/OfficeChairGrey_20" />
          <model name="OpenRobotics/OfficeChairGrey_21" />
          <model name="OpenRobotics/OfficeChairGrey_22" />
          <model name="OpenRobotics/OfficeChairGrey_23" />
          <model name="OpenRobotics/OfficeChairGrey_24" />
          <model name="OpenRobotics/LitterBin" />
          <model name="OpenRobotics/LitterBin_2" />
          <model name="OpenRobotics/Sofa" />
          <model name="OpenRobotics/Sofa_2" />
          <model name="OpenRobotics/Sofa_3" />
          <model name="OpenRobotics/Sofa_4" />
          <model name="OpenRobotics/AdjTable_13" />
          <model name="OpenRobotics/AdjTable_14" />
          <model name="OpenRobotics/AdjTable_15" />
          <model name="OpenRobotics/AdjTable_16" />
          <model name="OpenRobotics/AdjTable_17" />
          <model name="OpenRobotics/AdjTable_18" />
          <model name="OpenRobotics/AdjTable_19" />
          <model name="OpenRobotics/AdjTable_20" />
          <model name="OpenRobotics/AdjTable_21" />
          <model name="OpenRobotics/AdjTable_22" />
          <model name="OpenRobotics/AdjTable_23" />
          <model name="OpenRobotics/AdjTable_24" />
          <model name="OpenRobotics/AdjTable_25" />
          <model name="OpenRobotics/AdjTable_26" />
          <model name="OpenRobotics/AdjTable_27" />
          <model name="OpenRobotics/AdjTable_28" />
          <model name="OpenRobotics/AdjTable_29" />
          <model name="OpenRobotics/AdjTable_30" />
          <model name="OpenRobotics/OfficeChairGrey_25" />
          <model name="OpenRobotics/OfficeChairGrey_26" />
          <model name="OpenRobotics/OfficeChairGrey_27" />
          <model name="OpenRobotics/OfficeChairGrey_28" />
          <model name="OpenRobotics/OfficeChairGrey_29" />
          <model name="OpenRobotics/OfficeChairGrey_30" />
          <model name="OpenRobotics/OfficeChairGrey_31" />
          <model name="OpenRobotics/OfficeChairGrey_32" />
          <model name="OpenRobotics/OfficeChairGrey_33" />
          <model name="OpenRobotics/OfficeChairGrey_34" />
          <model name="OpenRobotics/OfficeChairGrey_35" />
          <model name="OpenRobotics/OfficeChairGrey_36" />
          <model name="OpenRobotics/OfficeChairGrey_37" />
          <model name="OpenRobotics/OfficeChairGrey_38" />
          <model name="OpenRobotics/OfficeChairGrey_39" />
          <model name="OpenRobotics/OfficeChairGrey_40" />
          <model name="OpenRobotics/OfficeChairGrey_41" />
          <model name="OpenRobotics/OfficeChairGrey_42" />
          <model name="OpenRobotics/OfficeChairGrey_43" />
          <model name="OpenRobotics/OfficeChairGrey_44" />
          <model name="OpenRobotics/OfficeChairGrey_45" />
          <model name="OpenRobotics/OfficeChairGrey_46" />
          <model name="OpenRobotics/OfficeChairGrey_47" />
          <model name="OpenRobotics/OfficeChairGrey_48" />
          <model name="OpenRobotics/OfficeChairGrey_49" />
          <model name="OpenRobotics/OfficeChairGrey_50" />
          <model name="OpenRobotics/OfficeChairGrey_51" />
          <model name="OpenRobotics/OfficeChairGrey_52" />
          <model name="OpenRobotics/OfficeChairGrey_53" />
          <model name="OpenRobotics/OfficeChairGrey_54" />
          <model name="OpenRobotics/OfficeChairGrey_55" />
          <model name="OpenRobotics/OfficeChairGrey_56" />
          <model name="OpenRobotics/OfficeChairGrey_57" />
          <model name="OpenRobotics/OfficeChairGrey_58" />
          <model name="OpenRobotics/OfficeChairGrey_59" />
          <model name="OpenRobotics/OfficeChairGrey_60" />
          <model name="OpenRobotics/AdjTable_31" />
          <model name="main_door_right" />
          <model name="main_door_left" />
          <model name="green_room_door" />
          <model name="side_room_door" />
          <model name="bottom_stairs_door" />
          <model name="ShaftDoor_lift_L1_door" />
        </floor>
        <floor name="L2" model_name="kioto_L2">
          <model name="OpenRobotics/AdjTable_32" />
          <model name="OpenRobotics/AdjTable_33" />
          <model name="OpenRobotics/AdjTable_34" />
          <model name="OpenRobotics/OfficeChairGrey_61" />
          <model name="OpenRobotics/OfficeChairGrey_62" />
          <model name="OpenRobotics/OfficeChairGrey_63" />
          <model name="OpenRobotics/OfficeChairGrey_64" />
          <model name="OpenRobotics/OfficeChairGrey_65" />
          <model name="OpenRobotics/OfficeChairGrey_66" />
          <model name="ShaftDoor_lift_L2_door" />
        </floor>
      </plugin>
    </gui>
    <light type="directional" name="sun">
      <cast_shadows>true</cast_shadows>
      <pose>0 0 10 0 0 0</pose>
      <diffuse>1 1 1 1</diffuse>
      <specular>0.2 0.2 0.2 1</specular>
      <attenuation>
        <range>1000</range>
        <constant>0.09</constant>
        <linear>0.001</linear>
        <quadratic>0.001</quadratic>
      </attenuation>
      <direction>-0.5 0.1 -0.9</direction>
    </light>
    <include>
      <name>OpenRobotics/AdjTable</name>
      <uri>https://fuel.gazebosim.org/1.0/OpenRobotics/models/AdjTable</uri>
      <pose>15.743016933868432 -11.24496494504982 0.0 0 0 0.0</pose>
      <static>True</static>
    </include>
    <include>
      <name>OpenRobotics/AdjTable_2</name>
      <uri>https://fuel.gazebosim.org/1.0/OpenRobotics/models/AdjTable</uri>
      <pose>17.379500799618157 -11.260553649047372 0.0 0 0 0.0</pose>
      <static>True</static>
    </include>
    <include>
      <name>OpenRobotics/AdjTable_3</name>
      <uri>https://fuel.gazebosim.org/1.0/OpenRobotics/models/AdjTable</uri>
      <pose>19.57588318207481 -11.242451456945979 0.0 0 0 -0.0013</pose>
      <static>True</static>
    </include>
    <include>
      <name>OpenRobotics/AdjTable_4</name>
      <uri>https://fuel.gazebosim.org/1.0/OpenRobotics/models/AdjTable</uri>
      <pose>21.194493354641676 -11.251109027081428 0.0 0 0 -0.0123</pose>
      <static>True</static>
    </include>
    <include>
      <name>OpenRobotics/AdjTable_5</name>
      <uri>https://fuel.gazebosim.org/1.0/OpenRobotics/models/AdjTable</uri>
      <pose>15.788107387125203 -14.11465747411092 0.0 0 0 0.0012</pose>
      <static>True</static>
    </include>
    <include>
      <name>OpenRobotics/AdjTable_6</name>
      <uri>https://fuel.gazebosim.org/1.0/OpenRobotics/models/AdjTable</uri>
      <pose>17.40356935237008 -14.11465747411092 0.0 0 0 -0.008</pose>
      <static>True</static>
    </include>
    <include>
      <name>OpenRobotics/AdjTable_7</name>
      <uri>https://fuel.gazebosim.org/1.0/OpenRobotics/models/AdjTable</uri>
      <pose>24.98569663336925 -11.251109027081428 0.0 0 0 0.0011</pose>
      <static>True</static>
    </include>
    <include>
      <name>OpenRobotics/AdjTable_8</name>
      <uri>https://fuel.gazebosim.org/1.0/OpenRobotics/models/AdjTable</uri>
      <pose>23.35842889066694 -11.242451456945979 0.0 0 0 0.0016</pose>
      <static>True</static>
    </include>
    <include>
      <name>OpenRobotics/AdjTable_9</name>
      <uri>https://fuel.gazebosim.org/1.0/OpenRobotics/models/AdjTable</uri>
      <pose>23.423703415060604 -14.076802819940964 0.0 0 0 0.0093</pose>
      <static>True</static>
    </include>
    <include>
      <name>OpenRobotics/AdjTable_10</name>
      <uri>https://fuel.gazebosim.org/1.0/OpenRobotics/models/AdjTable</uri>
      <pose>25.051808987130862 -14.089421037997615 0.0 0 0 0.0048</pose>
      <static>True</static>
    </include>
    <include>
      <name>OpenRobotics/AdjTable_11</name>
      <uri>https://fuel.gazebosim.org/1.0/OpenRobotics/models/AdjTable</uri>
      <pose>19.561741637894624 -14.102039256054267 0.0 0 0 -0.008</pose>
      <static>True</static>
    </include>
    <include>
      <name>OpenRobotics/AdjTable_12</name>
      <uri>https://fuel.gazebosim.org/1.0/OpenRobotics/models/AdjTable</uri>
      <pose>21.164585385082848 -14.076802819940964 0.0 0 0 0.0119</pose>
      <static>True</static>
    </include>
    <include>
      <name>OpenRobotics/OfficeChairGrey</name>
      <uri>https://fuel.gazebosim.org/1.0/OpenRobotics/models/OfficeChairGrey</uri>
      <pose>17.01763467897136 -11.742254758079278 0.0 0 0 3.1334</pose>
      <static>True</static>
    </include>
    <include>
      <name>OpenRobotics/OfficeChairGrey_2</name>
      <uri>https://fuel.gazebosim.org/1.0/OpenRobotics/models/OfficeChairGrey</uri>
      <pose>17.628234566823426 -11.732403915813723 0.0 0 0 -3.1369</pose>
      <static>True</static>
    </include>
    <include>
      <name>OpenRobotics/OfficeChairGrey_3</name>
      <uri>https://fuel.gazebosim.org/1.0/OpenRobotics/models/OfficeChairGrey</uri>
      <pose>19.97590862211628 -11.733851075631085 0.0 0 0 3.1343</pose>
      <static>True</static>
    </include>
    <include>
      <name>OpenRobotics/OfficeChairGrey_4</name>
      <uri>https://fuel.gazebosim.org/1.0/OpenRobotics/models/OfficeChairGrey</uri>
      <pose>19.33598470638607 -11.733851075631085 0.0 0 0 -3.1377</pose>
      <static>True</static>
    </include>
    <include>
      <name>OpenRobotics/OfficeChairGrey_5</name>
      <uri>https://fuel.gazebosim.org/1.0/OpenRobotics/models/OfficeChairGrey</uri>
      <pose>21.45267174381289 -11.733851075631085 0.0 0 0 3.1371</pose>
      <static>True</static>
    </include>
    <include>
      <name>OpenRobotics/OfficeChairGrey_6</name>
      <uri>https://fuel.gazebosim.org/1.0/OpenRobotics/models/OfficeChairGrey</uri>
      <pose>20.86195126187301 -11.742051647929474 0.0 0 0 3.1129</pose>
      <static>True</static>
    </include>
    <include>
      <name>OpenRobotics/OfficeChairGrey_7</name>
      <uri>https://fuel.gazebosim.org/1.0/OpenRobotics/models/OfficeChairGrey</uri>
      <pose>15.523074030398059 -14.594251315338596 0.0 0 0 3.1225</pose>
      <static>True</static>
    </include>
    <include>
      <name>OpenRobotics/OfficeChairGrey_8</name>
      <uri>https://fuel.gazebosim.org/1.0/OpenRobotics/models/OfficeChairGrey</uri>
      <pose>16.091020786791024 -14.644749576333929 0.0 0 0 -3.1387</pose>
      <static>True</static>
    </include>
    <include>
      <name>OpenRobotics/OfficeChairGrey_9</name>
      <uri>https://fuel.gazebosim.org/1.0/OpenRobotics/models/OfficeChairGrey</uri>
      <pose>17.58027518270066 -14.644749576333929 0.0 0 0 3.1209</pose>
      <static>True</static>
    </include>
    <include>
      <name>OpenRobotics/OfficeChairGrey_10</name>
      <uri>https://fuel.gazebosim.org/1.0/OpenRobotics/models/OfficeChairGrey</uri>
      <pose>16.923975511142405 -14.594251315338596 0.0 0 0 3.1356</pose>
      <static>True</static>
    </include>
    <include>
      <name>OpenRobotics/OfficeChairGrey_11</name>
      <uri>https://fuel.gazebosim.org/1.0/OpenRobotics/models/OfficeChairGrey</uri>
      <pose>19.96560078201366 -14.644749576333929 0.0 0 0 3.1225</pose>
      <static>True</static>
    </include>
    <include>
      <name>OpenRobotics/OfficeChairGrey_12</name>
      <uri>https://fuel.gazebosim.org/1.0/OpenRobotics/models/OfficeChairGrey</uri>
      <pose>19.34718115339409 -14.632131358277276 0.0 0 0 3.1271</pose>
      <static>True</static>
    </include>
    <include>
      <name>OpenRobotics/OfficeChairGrey_13</name>
      <uri>https://fuel.gazebosim.org/1.0/OpenRobotics/models/OfficeChairGrey</uri>
      <pose>21.41700052375334 -14.65736779439058 0.0 0 0 3.1407</pose>
      <static>True</static>
    </include>
    <include>
      <name>OpenRobotics/OfficeChairGrey_14</name>
      <uri>https://fuel.gazebosim.org/1.0/OpenRobotics/models/OfficeChairGrey</uri>
      <pose>20.76072624096381 -14.65736779439058 0.0 0 0 3.1259</pose>
      <static>True</static>
    </include>
    <include>
      <name>OpenRobotics/OfficeChairGrey_15</name>
      <uri>https://fuel.gazebosim.org/1.0/OpenRobotics/models/OfficeChairGrey</uri>
      <pose>23.72661681472643 -14.632131358277276 0.0 0 0 3.1062</pose>
      <static>True</static>
    </include>
    <include>
      <name>OpenRobotics/OfficeChairGrey_16</name>
      <uri>https://fuel.gazebosim.org/1.0/OpenRobotics/models/OfficeChairGrey</uri>
      <pose>23.095578968050205 -14.66998601244723 0.0 0 0 -3.138</pose>
      <static>True</static>
    </include>
    <include>
      <name>OpenRobotics/OfficeChairGrey_17</name>
      <uri>https://fuel.gazebosim.org/1.0/OpenRobotics/models/OfficeChairGrey</uri>
      <pose>15.49641582323612 -11.717449931034311 0.0 0 0 3.1261</pose>
      <static>True</static>
    </include>
    <include>
      <name>OpenRobotics/OfficeChairGrey_18</name>
      <uri>https://fuel.gazebosim.org/1.0/OpenRobotics/models/OfficeChairGrey</uri>
      <pose>16.152740883563098 -11.733851075631085 0.0 0 0 3.1205</pose>
      <static>True</static>
    </include>
    <include>
      <name>OpenRobotics/OfficeChairGrey_19</name>
      <uri>https://fuel.gazebosim.org/1.0/OpenRobotics/models/OfficeChairGrey</uri>
      <pose>23.758048110408794 -11.77487932589175 0.0 0 0 -3.1397</pose>
      <static>True</static>
    </include>
    <include>
      <name>OpenRobotics/OfficeChairGrey_20</name>
      <uri>https://fuel.gazebosim.org/1.0/OpenRobotics/models/OfficeChairGrey</uri>
      <pose>23.134525339275363 -11.77487932589175 0.0 0 0 3.1323</pose>
      <static>True</static>
    </include>
    <include>
      <name>OpenRobotics/OfficeChairGrey_21</name>
      <uri>https://fuel.gazebosim.org/1.0/OpenRobotics/models/OfficeChairGrey</uri>
      <pose>25.30044119926123 -11.758478181294974 0.0 0 0 3.1237</pose>
      <static>True</static>
    </include>
    <include>
      <name>OpenRobotics/OfficeChairGrey_22</name>
      <uri>https://fuel.gazebosim.org/1.0/OpenRobotics/models/OfficeChairGrey</uri>
      <pose>24.594861927606473 -11.758478181294974 0.0 0 0 -3.1364</pose>
      <static>True</static>
    </include>
    <include>
      <name>OpenRobotics/OfficeChairGrey_23</name>
      <uri>https://fuel.gazebosim.org/1.0/OpenRobotics/models/OfficeChairGrey</uri>
      <pose>25.19063477452276 -14.619513140220626 0.0 0 0 3.1303</pose>
      <static>True</static>
    </include>
    <include>
      <name>OpenRobotics/OfficeChairGrey_24</name>
      <uri>https://fuel.gazebosim.org/1.0/OpenRobotics/models/OfficeChairGrey</uri>
      <pose>24.546953321021157 -14.594251315338596 0.0 0 0 -3.1379</pose>
      <static>True</static>
    </include>
    <include>
      <name>OpenRobotics/LitterBin</name>
      <uri>https://fuel.gazebosim.org/1.0/OpenRobotics/models/LitterBin</uri>
      <pose>23.671116966292143 -26.78446550881338 0.0 0 0 1.5708</pose>
      <static>True</static>
    </include>
    <include>
      <name>OpenRobotics/LitterBin_2</name>
      <uri>https://fuel.gazebosim.org/1.0/OpenRobotics/models/LitterBin</uri>
      <pose>27.448178700839524 -26.73089520680224 0.0 0 0 1.5708</pose>
      <static>True</static>
    </include>
    <include>
      <name>OpenRobotics/Sofa</name>
      <uri>https://fuel.gazebosim.org/1.0/OpenRobotics/models/Sofa</uri>
      <pose>28.806757104118198 -40.720233718483314 0.0 0 0 0.0</pose>
      <static>True</static>
    </include>
    <include>
      <name>OpenRobotics/Sofa_2</name>
      <uri>https://fuel.gazebosim.org/1.0/OpenRobotics/models/Sofa</uri>
      <pose>28.765551132476457 -42.91813942706351 0.0 0 0 0.0</pose>
      <static>True</static>
    </include>
    <include>
      <name>OpenRobotics/Sofa_3</name>
      <uri>https://fuel.gazebosim.org/1.0/OpenRobotics/models/Sofa</uri>
      <pose>31.293155391728043 -42.91813942706351 0.0 0 0 3.1416</pose>
      <static>True</static>
    </include>
    <include>
      <name>OpenRobotics/Sofa_4</name>
      <uri>https://fuel.gazebosim.org/1.0/OpenRobotics/models/Sofa</uri>
      <pose>31.224478772325142 -40.59659041478936 0.0 0 0 3.1416</pose>
      <static>True</static>
    </include>
    <include>
      <name>OpenRobotics/AdjTable_13</name>
      <uri>https://fuel.gazebosim.org/1.0/OpenRobotics/models/AdjTable</uri>
      <pose>15.775489169068548 -16.79027825503309 0.0 0 0 -0.0294</pose>
      <static>True</static>
    </include>
    <include>
      <name>OpenRobotics/AdjTable_14</name>
      <uri>https://fuel.gazebosim.org/1.0/OpenRobotics/models/AdjTable</uri>
      <pose>17.378332916256777 -16.815514691146397 0.0 0 0 0.0</pose>
      <static>True</static>
    </include>
    <include>
      <name>OpenRobotics/AdjTable_15</name>
      <uri>https://fuel.gazebosim.org/1.0/OpenRobotics/models/AdjTable</uri>
      <pose>19.561741637894624 -16.878631170198382 0.0 0 0 0.027</pose>
      <static>True</static>
    </include>
    <include>
      <name>OpenRobotics/AdjTable_16</name>
      <uri>https://fuel.gazebosim.org/1.0/OpenRobotics/models/AdjTable</uri>
      <pose>21.189821821196155 -16.878631170198382 0.0 0 0 0.0</pose>
      <static>True</static>
    </include>
    <include>
      <name>OpenRobotics/AdjTable_17</name>
      <uri>https://fuel.gazebosim.org/1.0/OpenRobotics/models/AdjTable</uri>
      <pose>23.360612324777346 -16.802896473089742 0.0 0 0 0.0</pose>
      <static>True</static>
    </include>
    <include>
      <name>OpenRobotics/AdjTable_18</name>
      <uri>https://fuel.gazebosim.org/1.0/OpenRobotics/models/AdjTable</uri>
      <pose>24.976074290022225 -16.79027825503309 0.0 0 0 0.0139</pose>
      <static>True</static>
    </include>
    <include>
      <name>OpenRobotics/AdjTable_19</name>
      <uri>https://fuel.gazebosim.org/1.0/OpenRobotics/models/AdjTable</uri>
      <pose>15.737634514898593 -19.65519769557377 0.0 0 0 0.0133</pose>
      <static>True</static>
    </include>
    <include>
      <name>OpenRobotics/AdjTable_20</name>
      <uri>https://fuel.gazebosim.org/1.0/OpenRobotics/models/AdjTable</uri>
      <pose>17.340478262086823 -19.667841302399147 0.0 0 0 -0.0028</pose>
      <static>True</static>
    </include>
    <include>
      <name>OpenRobotics/AdjTable_21</name>
      <uri>https://fuel.gazebosim.org/1.0/OpenRobotics/models/AdjTable</uri>
      <pose>19.662712771116563 -19.667841302399147 0.0 0 0 0.0169</pose>
      <static>True</static>
    </include>
    <include>
      <name>OpenRobotics/AdjTable_22</name>
      <uri>https://fuel.gazebosim.org/1.0/OpenRobotics/models/AdjTable</uri>
      <pose>21.26555651830479 -19.62996125946046 0.0 0 0 0.0303</pose>
      <static>True</static>
    </include>
    <include>
      <name>OpenRobotics/AdjTable_23</name>
      <uri>https://fuel.gazebosim.org/1.0/OpenRobotics/models/AdjTable</uri>
      <pose>23.360612324777346 -19.566870169177207 0.0 0 0 0.0</pose>
      <static>True</static>
    </include>
    <include>
      <name>OpenRobotics/AdjTable_24</name>
      <uri>https://fuel.gazebosim.org/1.0/OpenRobotics/models/AdjTable</uri>
      <pose>24.93821963585227 -19.617343041403814 0.0 0 0 0.0</pose>
      <static>True</static>
    </include>
    <include>
      <name>OpenRobotics/AdjTable_25</name>
      <uri>https://fuel.gazebosim.org/1.0/OpenRobotics/models/AdjTable</uri>
      <pose>15.737634514898593 -22.40655317360458 0.0 0 0 0.0</pose>
      <static>True</static>
    </include>
    <include>
      <name>OpenRobotics/AdjTable_26</name>
      <uri>https://fuel.gazebosim.org/1.0/OpenRobotics/models/AdjTable</uri>
      <pose>17.327860044030167 -22.38131673749127 0.0 0 0 0.0</pose>
      <static>True</static>
    </include>
    <include>
      <name>OpenRobotics/AdjTable_27</name>
      <uri>https://fuel.gazebosim.org/1.0/OpenRobotics/models/AdjTable</uri>
      <pose>19.65009455305991 -22.41917139166123 0.0 0 0 0.0244</pose>
      <static>True</static>
    </include>
    <include>
      <name>OpenRobotics/AdjTable_28</name>
      <uri>https://fuel.gazebosim.org/1.0/OpenRobotics/models/AdjTable</uri>
      <pose>21.3412658266447 -22.41917139166123 0.0 0 0 0.0204</pose>
      <static>True</static>
    </include>
    <include>
      <name>OpenRobotics/AdjTable_29</name>
      <uri>https://fuel.gazebosim.org/1.0/OpenRobotics/models/AdjTable</uri>
      <pose>23.411085197003956 -22.393934955547927 0.0 0 0 -0.007</pose>
      <static>True</static>
    </include>
    <include>
      <name>OpenRobotics/AdjTable_30</name>
      <uri>https://fuel.gazebosim.org/1.0/OpenRobotics/models/AdjTable</uri>
      <pose>24.963456071965574 -22.41917139166123 0.0 0 0 0.0</pose>
      <static>True</static>
    </include>
    <include>
      <name>OpenRobotics/OfficeChairGrey_25</name>
      <uri>https://fuel.gazebosim.org/1.0/OpenRobotics/models/OfficeChairGrey</uri>
      <pose>15.523074030398059 -17.345606793369406 0.0 0 0 -3.1249</pose>
      <static>True</static>
    </include>
    <include>
      <name>OpenRobotics/OfficeChairGrey_26</name>
      <uri>https://fuel.gazebosim.org/1.0/OpenRobotics/models/OfficeChairGrey</uri>
      <pose>16.154111877074282 -17.30772675043072 0.0 0 0 -3.1416</pose>
      <static>True</static>
    </include>
    <include>
      <name>OpenRobotics/OfficeChairGrey_27</name>
      <uri>https://fuel.gazebosim.org/1.0/OpenRobotics/models/OfficeChairGrey</uri>
      <pose>17.075444905359678 -17.358225011426057 0.0 0 0 -3.1095</pose>
      <static>True</static>
    </include>
    <include>
      <name>OpenRobotics/OfficeChairGrey_28</name>
      <uri>https://fuel.gazebosim.org/1.0/OpenRobotics/models/OfficeChairGrey</uri>
      <pose>17.66860270909722 -17.358225011426057 0.0 0 0 -3.1093</pose>
      <static>True</static>
    </include>
    <include>
      <name>OpenRobotics/OfficeChairGrey_29</name>
      <uri>https://fuel.gazebosim.org/1.0/OpenRobotics/models/OfficeChairGrey</uri>
      <pose>19.385035807564044 -17.408697883652664 0.0 0 0 3.1062</pose>
      <static>True</static>
    </include>
    <include>
      <name>OpenRobotics/OfficeChairGrey_30</name>
      <uri>https://fuel.gazebosim.org/1.0/OpenRobotics/models/OfficeChairGrey</uri>
      <pose>19.927746127843704 -17.396079665596012 0.0 0 0 -3.0775</pose>
      <static>True</static>
    </include>
    <include>
      <name>OpenRobotics/OfficeChairGrey_31</name>
      <uri>https://fuel.gazebosim.org/1.0/OpenRobotics/models/OfficeChairGrey</uri>
      <pose>20.886933810299055 -17.38346144753936 0.0 0 0 3.1077</pose>
      <static>True</static>
    </include>
    <include>
      <name>OpenRobotics/OfficeChairGrey_32</name>
      <uri>https://fuel.gazebosim.org/1.0/OpenRobotics/models/OfficeChairGrey</uri>
      <pose>21.50535343891863 -17.446577926591345 0.0 0 0 -3.1077</pose>
      <static>True</static>
    </include>
    <include>
      <name>OpenRobotics/OfficeChairGrey_33</name>
      <uri>https://fuel.gazebosim.org/1.0/OpenRobotics/models/OfficeChairGrey</uri>
      <pose>23.13343362222016 -17.370843229482706 0.0 0 0 3.134</pose>
      <static>True</static>
    </include>
    <include>
      <name>OpenRobotics/OfficeChairGrey_34</name>
      <uri>https://fuel.gazebosim.org/1.0/OpenRobotics/models/OfficeChairGrey</uri>
      <pose>23.711383553491036 -17.352436372156607 0.0 0 0 -3.1231</pose>
      <static>True</static>
    </include>
    <include>
      <name>OpenRobotics/OfficeChairGrey_35</name>
      <uri>https://fuel.gazebosim.org/1.0/OpenRobotics/models/OfficeChairGrey</uri>
      <pose>24.63512851480537 -17.35774262482027 0.0 0 0 -3.1416</pose>
      <static>True</static>
    </include>
    <include>
      <name>OpenRobotics/OfficeChairGrey_36</name>
      <uri>https://fuel.gazebosim.org/1.0/OpenRobotics/models/OfficeChairGrey</uri>
      <pose>25.190939439747467 -17.37627642599 0.0 0 0 3.1275</pose>
      <static>True</static>
    </include>
    <include>
      <name>OpenRobotics/OfficeChairGrey_37</name>
      <uri>https://fuel.gazebosim.org/1.0/OpenRobotics/models/OfficeChairGrey</uri>
      <pose>15.551306341220993 -20.141392616670114 0.0 0 0 3.1065</pose>
      <static>True</static>
    </include>
    <include>
      <name>OpenRobotics/OfficeChairGrey_38</name>
      <uri>https://fuel.gazebosim.org/1.0/OpenRobotics/models/OfficeChairGrey</uri>
      <pose>16.110214695947622 -20.187650953288262 0.0 0 0 -3.0945</pose>
      <static>True</static>
    </include>
    <include>
      <name>OpenRobotics/OfficeChairGrey_39</name>
      <uri>https://fuel.gazebosim.org/1.0/OpenRobotics/models/OfficeChairGrey</uri>
      <pose>17.010271936040915 -20.133674430977514 0.0 0 0 -3.0946</pose>
      <static>True</static>
    </include>
    <include>
      <name>OpenRobotics/OfficeChairGrey_40</name>
      <uri>https://fuel.gazebosim.org/1.0/OpenRobotics/models/OfficeChairGrey</uri>
      <pose>17.61546401615442 -20.15487405286344 0.0 0 0 3.1133</pose>
      <static>True</static>
    </include>
    <include>
      <name>OpenRobotics/OfficeChairGrey_41</name>
      <uri>https://fuel.gazebosim.org/1.0/OpenRobotics/models/OfficeChairGrey</uri>
      <pose>19.367390613299712 -20.20306193590474 0.0 0 0 -3.1234</pose>
      <static>True</static>
    </include>
    <include>
      <name>OpenRobotics/OfficeChairGrey_42</name>
      <uri>https://fuel.gazebosim.org/1.0/OpenRobotics/models/OfficeChairGrey</uri>
      <pose>19.974512239836365 -20.206921028751037 0.0 0 0 -3.1327</pose>
      <static>True</static>
    </include>
    <include>
      <name>OpenRobotics/OfficeChairGrey_43</name>
      <uri>https://fuel.gazebosim.org/1.0/OpenRobotics/models/OfficeChairGrey</uri>
      <pose>20.853369858043735 -20.16259223855604 0.0 0 0 -3.0906</pose>
      <static>True</static>
    </include>
    <include>
      <name>OpenRobotics/OfficeChairGrey_44</name>
      <uri>https://fuel.gazebosim.org/1.0/OpenRobotics/models/OfficeChairGrey</uri>
      <pose>21.458536549388516 -20.14715586717084 0.0 0 0 3.1203</pose>
      <static>True</static>
    </include>
    <include>
      <name>OpenRobotics/OfficeChairGrey_45</name>
      <uri>https://fuel.gazebosim.org/1.0/OpenRobotics/models/OfficeChairGrey</uri>
      <pose>23.118708136359277 -20.101430694695928 0.0 0 0 3.1016</pose>
      <static>True</static>
    </include>
    <include>
      <name>OpenRobotics/OfficeChairGrey_46</name>
      <uri>https://fuel.gazebosim.org/1.0/OpenRobotics/models/OfficeChairGrey</uri>
      <pose>23.74555683619577 -20.127174906183747 0.0 0 0 -3.1416</pose>
      <static>True</static>
    </include>
    <include>
      <name>OpenRobotics/OfficeChairGrey_47</name>
      <uri>https://fuel.gazebosim.org/1.0/OpenRobotics/models/OfficeChairGrey</uri>
      <pose>24.60166611762495 -20.131846439629268 0.0 0 0 -3.1199</pose>
      <static>True</static>
    </include>
    <include>
      <name>OpenRobotics/OfficeChairGrey_48</name>
      <uri>https://fuel.gazebosim.org/1.0/OpenRobotics/models/OfficeChairGrey</uri>
      <pose>25.17004448308625 -20.13651797307479 0.0 0 0 3.0879</pose>
      <static>True</static>
    </include>
    <include>
      <name>OpenRobotics/OfficeChairGrey_49</name>
      <uri>https://fuel.gazebosim.org/1.0/OpenRobotics/models/OfficeChairGrey</uri>
      <pose>15.537291740884429 -22.911561172326635 0.0 0 0 3.1028</pose>
      <static>True</static>
    </include>
    <include>
      <name>OpenRobotics/OfficeChairGrey_50</name>
      <uri>https://fuel.gazebosim.org/1.0/OpenRobotics/models/OfficeChairGrey</uri>
      <pose>16.149541898703667 -22.926108936806436 0.0 0 0 3.1138</pose>
      <static>True</static>
    </include>
    <include>
      <name>OpenRobotics/OfficeChairGrey_51</name>
      <uri>https://fuel.gazebosim.org/1.0/OpenRobotics/models/OfficeChairGrey</uri>
      <pose>17.01799012173352 -22.915217155023132 0.0 0 0 3.1312</pose>
      <static>True</static>
    </include>
    <include>
      <name>OpenRobotics/OfficeChairGrey_52</name>
      <uri>https://fuel.gazebosim.org/1.0/OpenRobotics/models/OfficeChairGrey</uri>
      <pose>17.648418637960322 -22.9188477489509 0.0 0 0 -3.1281</pose>
      <static>True</static>
    </include>
    <include>
      <name>OpenRobotics/OfficeChairGrey_53</name>
      <uri>https://fuel.gazebosim.org/1.0/OpenRobotics/models/OfficeChairGrey</uri>
      <pose>19.36952326987267 -22.931796021000984 0.0 0 0 3.1236</pose>
      <static>True</static>
    </include>
    <include>
      <name>OpenRobotics/OfficeChairGrey_54</name>
      <uri>https://fuel.gazebosim.org/1.0/OpenRobotics/models/OfficeChairGrey</uri>
      <pose>19.93282388158884 -22.95505213315369 0.0 0 0 -3.0986</pose>
      <static>True</static>
    </include>
    <include>
      <name>OpenRobotics/OfficeChairGrey_55</name>
      <uri>https://fuel.gazebosim.org/1.0/OpenRobotics/models/OfficeChairGrey</uri>
      <pose>20.881094393492152 -22.973128936486358 0.0 0 0 -3.0899</pose>
      <static>True</static>
    </include>
    <include>
      <name>OpenRobotics/OfficeChairGrey_56</name>
      <uri>https://fuel.gazebosim.org/1.0/OpenRobotics/models/OfficeChairGrey</uri>
      <pose>21.485727920693694 -22.967975016435048 0.0 0 0 -3.0904</pose>
      <static>True</static>
    </include>
    <include>
      <name>OpenRobotics/OfficeChairGrey_57</name>
      <uri>https://fuel.gazebosim.org/1.0/OpenRobotics/models/OfficeChairGrey</uri>
      <pose>23.123887445179314 -22.91293216583782 0.0 0 0 3.1261</pose>
      <static>True</static>
    </include>
    <include>
      <name>OpenRobotics/OfficeChairGrey_58</name>
      <uri>https://fuel.gazebosim.org/1.0/OpenRobotics/models/OfficeChairGrey</uri>
      <pose>23.766756458081694 -22.956829346964483 0.0 0 0 3.1016</pose>
      <static>True</static>
    </include>
    <include>
      <name>OpenRobotics/OfficeChairGrey_59</name>
      <uri>https://fuel.gazebosim.org/1.0/OpenRobotics/models/OfficeChairGrey</uri>
      <pose>24.616569324866912 -22.947435502535992 0.0 0 0 -3.1277</pose>
      <static>True</static>
    </include>
    <include>
      <name>OpenRobotics/OfficeChairGrey_60</name>
      <uri>https://fuel.gazebosim.org/1.0/OpenRobotics/models/OfficeChairGrey</uri>
      <pose>25.190431664372955 -22.959977554286468 0.0 0 0 3.1269</pose>
      <static>True</static>
    </include>
    <include>
      <name>OpenRobotics/AdjTable_31</name>
      <uri>https://fuel.gazebosim.org/1.0/OpenRobotics/models/AdjTable</uri>
      <pose>18.62718106110316 -38.86591421706744 0.0 0 0 0.0256</pose>
      <static>True</static>
    </include>
    <include>
      <name>tinyrobot2</name>
      <uri>model://TinyRobot</uri>
      <pose>14.742115504396825 -7.8907785423969905 0.0 0 0 0.008324469518936966</pose>
    </include>
    <include>
      <name>tinyrobot1</name>
      <uri>model://TinyRobot</uri>
      <pose>22.63959668173739 -26.383145241566904 0.0 0 0 0.014492767689360206</pose>
    </include>
    <model name="main_door_right">
      <pose>22.008558835061166 -31.59895041664423 0.0 0 0 3.141583949309029</pose>
      <link name="right">
        <pose>0.7292035209816043 0 1.11 0 0 0</pose>
        <visual name="right_visual">
          <geometry>
            <box>
              <size>1.4484070419632087 0.03 2.2</size>
            </box>
          </geometry>
          <material>
            <ambient>0.5 0.25 0 0.6</ambient>
            <diffuse>0.5 0.25 0 0.6</diffuse>
            <pbr>
              <metal>
                <metalness>0.0</metalness>
              </metal>
            </pbr>
          </material>
        </visual>
        <collision name="right_collision">
          <geometry>
            <box>
              <size>1.4484070419632087 0.03 2.2</size>
            </box>
          </geometry>
          <surface>
            <contact>
              <collide_bitmask>0x02</collide_bitmask>
            </contact>
          </surface>
        </collision>
        <inertial>
          <mass>50.0</mass>
          <inertia>
            <ixx>20.17041666666667</ixx>
            <iyy>28.907845663369223</iyy>
            <izz>8.744928996702553</izz>
          </inertia>
        </inertial>
      </link>
      <joint name="right_joint" type="revolute">
        <parent>world</parent>
        <child>right</child>
        <axis>
          <xyz>0 0 -1</xyz>
          <limit>
            <lower>0</lower>
            <upper>1.57</upper>
          </limit>
        </axis>
        <pose>0.7292035209816043 0 0 0 0 0</pose>
      </joint>
      <link name="left">
        <pose>-0.7292035209816043 0 1.11 0 0 0</pose>
        <visual name="left_visual">
          <geometry>
            <box>
              <size>1.4484070419632087 0.03 2.2</size>
            </box>
          </geometry>
          <material>
            <ambient>0.5 0.25 0 0.6</ambient>
            <diffuse>0.5 0.25 0 0.6</diffuse>
            <pbr>
              <metal>
                <metalness>0.0</metalness>
              </metal>
            </pbr>
          </material>
        </visual>
        <collision name="left_collision">
          <geometry>
            <box>
              <size>1.4484070419632087 0.03 2.2</size>
            </box>
          </geometry>
          <surface>
            <contact>
              <collide_bitmask>0x02</collide_bitmask>
            </contact>
          </surface>
        </collision>
        <inertial>
          <mass>50.0</mass>
          <inertia>
            <ixx>20.17041666666667</ixx>
            <iyy>28.907845663369223</iyy>
            <izz>8.744928996702553</izz>
          </inertia>
        </inertial>
      </link>
      <joint name="left_joint" type="revolute">
        <parent>world</parent>
        <child>left</child>
        <axis>
          <xyz>0 0 -1</xyz>
          <limit>
            <lower>-1.57</lower>
            <upper>0</upper>
          </limit>
        </axis>
        <pose>-0.7292035209816043 0 0 0 0 0</pose>
      </joint>
      <plugin name="register_component" filename="libregister_component.so">
        <component name="Door">
          <v_max_door>0.5</v_max_door>
          <a_max_door>0.3</a_max_door>
          <a_nom_door>0.15</a_nom_door>
          <dx_min_door>0.01</dx_min_door>
          <f_max_door>500.0</f_max_door>
          <ros_interface>true</ros_interface>
          <door name="main_door_right" type="DoubleSwingDoor" left_joint_name="left_joint" right_joint_name="right_joint" />
        </component>
      </plugin>
    </model>
    <model name="main_door_left">
      <pose>18.701532070316247 -31.60091804622047 0.0 0 0 0.001323547354239751</pose>
      <link name="right">
        <pose>0.7481124617256443 0 1.11 0 0 0</pose>
        <visual name="right_visual">
          <geometry>
            <box>
              <size>1.4862249234512885 0.03 2.2</size>
            </box>
          </geometry>
          <material>
            <ambient>0.5 0.25 0 0.6</ambient>
            <diffuse>0.5 0.25 0 0.6</diffuse>
            <pbr>
              <metal>
                <metalness>0.0</metalness>
              </metal>
            </pbr>
          </material>
        </visual>
        <collision name="right_collision">
          <geometry>
            <box>
              <size>1.4862249234512885 0.03 2.2</size>
            </box>
          </geometry>
          <surface>
            <contact>
              <collide_bitmask>0x02</collide_bitmask>
            </contact>
          </surface>
        </collision>
        <inertial>
          <mass>50.0</mass>
          <inertia>
            <ixx>20.17041666666667</ixx>
            <iyy>29.370268846199124</iyy>
            <izz>9.207352179532453</izz>
          </inertia>
        </inertial>
      </link>
      <joint name="right_joint" type="revolute">
        <parent>world</parent>
        <child>right</child>
        <axis>
          <xyz>0 0 1</xyz>
          <limit>
            <lower>0</lower>
            <upper>1.57</upper>
          </limit>
        </axis>
        <pose>0.7481124617256443 0 0 0 0 0</pose>
      </joint>
      <link name="left">
        <pose>-0.7481124617256443 0 1.11 0 0 0</pose>
        <visual name="left_visual">
          <geometry>
            <box>
              <size>1.4862249234512885 0.03 2.2</size>
            </box>
          </geometry>
          <material>
            <ambient>0.5 0.25 0 0.6</ambient>
            <diffuse>0.5 0.25 0 0.6</diffuse>
            <pbr>
              <metal>
                <metalness>0.0</metalness>
              </metal>
            </pbr>
          </material>
        </visual>
        <collision name="left_collision">
          <geometry>
            <box>
              <size>1.4862249234512885 0.03 2.2</size>
            </box>
          </geometry>
          <surface>
            <contact>
              <collide_bitmask>0x02</collide_bitmask>
            </contact>
          </surface>
        </collision>
        <inertial>
          <mass>50.0</mass>
          <inertia>
            <ixx>20.17041666666667</ixx>
            <iyy>29.370268846199124</iyy>
            <izz>9.207352179532453</izz>
          </inertia>
        </inertial>
      </link>
      <joint name="left_joint" type="revolute">
        <parent>world</parent>
        <child>left</child>
        <axis>
          <xyz>0 0 1</xyz>
          <limit>
            <lower>-1.57</lower>
            <upper>0</upper>
          </limit>
        </axis>
        <pose>-0.7481124617256443 0 0 0 0 0</pose>
      </joint>
      <plugin name="register_component" filename="libregister_component.so">
        <component name="Door">
          <v_max_door>0.5</v_max_door>
          <a_max_door>0.3</a_max_door>
          <a_nom_door>0.15</a_nom_door>
          <dx_min_door>0.01</dx_min_door>
          <f_max_door>500.0</f_max_door>
          <ros_interface>true</ros_interface>
          <door name="main_door_left" type="DoubleSwingDoor" left_joint_name="left_joint" right_joint_name="right_joint" />
        </component>
      </plugin>
    </model>
    <model name="green_room_door">
      <pose>17.205308457391418 -34.86200383395631 0.0 0 0 1.5707963267948966</pose>
      <link name="right">
        <pose>0 0 1.11 0 0 0</pose>
        <visual name="right_visual">
          <geometry>
            <box>
              <size>0.9636592806289792 0.03 2.2</size>
            </box>
          </geometry>
          <material>
            <ambient>0.5 0.25 0 0.6</ambient>
            <diffuse>0.5 0.25 0 0.6</diffuse>
            <pbr>
              <metal>
                <metalness>0.0</metalness>
              </metal>
            </pbr>
          </material>
        </visual>
        <collision name="right_collision">
          <geometry>
            <box>
              <size>0.9636592806289792 0.03 2.2</size>
            </box>
          </geometry>
          <surface>
            <contact>
              <collide_bitmask>0x02</collide_bitmask>
            </contact>
          </surface>
        </collision>
        <inertial>
          <mass>50.0</mass>
          <inertia>
            <ixx>20.17041666666667</ixx>
            <iyy>24.035996704759846</iyy>
            <izz>3.8730800380931742</izz>
          </inertia>
        </inertial>
      </link>
      <joint name="right_joint" type="revolute">
        <parent>world</parent>
        <child>right</child>
        <axis>
          <xyz>0 0 1</xyz>
          <limit>
            <lower>0</lower>
            <upper>1.57</upper>
          </limit>
        </axis>
        <pose>0.4868296403144896 0 0 0 0 0</pose>
      </joint>
      <plugin name="register_component" filename="libregister_component.so">
        <component name="Door">
          <v_max_door>0.5</v_max_door>
          <a_max_door>0.3</a_max_door>
          <a_nom_door>0.15</a_nom_door>
          <dx_min_door>0.01</dx_min_door>
          <f_max_door>500.0</f_max_door>
          <ros_interface>true</ros_interface>
          <door name="green_room_door" type="SwingDoor" left_joint_name="empty_joint" right_joint_name="right_joint" />
        </component>
      </plugin>
    </model>
    <model name="side_room_door">
      <pose>23.466965876969127 -34.816849908777726 0.0 0 0 1.5707963267948966</pose>
      <static>true</static>
      <link name="right">
        <pose>0 0 1.11 0 0 0</pose>
        <visual name="right_visual">
          <geometry>
            <box>
              <size>0.8754333093073166 0.03 2.2</size>
            </box>
          </geometry>
          <material>
            <ambient>0.5 0.25 0 0.6</ambient>
            <diffuse>0.5 0.25 0 0.6</diffuse>
            <pbr>
              <metal>
                <metalness>0.0</metalness>
              </metal>
            </pbr>
          </material>
        </visual>
        <collision name="right_collision">
          <geometry>
            <box>
              <size>0.8754333093073166 0.03 2.2</size>
            </box>
          </geometry>
          <surface>
            <contact>
              <collide_bitmask>0x02</collide_bitmask>
            </contact>
          </surface>
        </collision>
        <inertial>
          <mass>50.0</mass>
          <inertia>
            <ixx>20.17041666666667</ixx>
            <iyy>23.359931162686504</iyy>
            <izz>3.1970144960198326</izz>
          </inertia>
        </inertial>
      </link>
      <joint name="right_joint" type="revolute">
        <parent>world</parent>
        <child>right</child>
        <axis>
          <xyz>0 0 -1</xyz>
          <limit>
            <lower>0</lower>
            <upper>1.57</upper>
          </limit>
        </axis>
        <pose>0.4427166546536583 0 0 0 0 0</pose>
      </joint>
    </model>
    <model name="bottom_stairs_door">
      <pose>17.004381741696562 -43.25836162237169 0.0 0 0 1.5629671816468744</pose>
      <static>true</static>
      <link name="right">
        <pose>0.47508285335173855 0 1.11 0 0 0</pose>
        <visual name="right_visual">
          <geometry>
            <box>
              <size>0.9401657067034771 0.03 2.2</size>
            </box>
          </geometry>
          <material>
            <ambient>0.5 0.25 0 0.6</ambient>
            <diffuse>0.5 0.25 0 0.6</diffuse>
            <pbr>
              <metal>
                <metalness>0.0</metalness>
              </metal>
            </pbr>
          </material>
        </visual>
        <collision name="right_collision">
          <geometry>
            <box>
              <size>0.9401657067034771 0.03 2.2</size>
            </box>
          </geometry>
          <surface>
            <contact>
              <collide_bitmask>0x02</collide_bitmask>
            </contact>
          </surface>
        </collision>
        <inertial>
          <mass>50.0</mass>
          <inertia>
            <ixx>20.17041666666667</ixx>
            <iyy>23.849631483588542</iyy>
            <izz>3.686714816921869</izz>
          </inertia>
        </inertial>
      </link>
      <joint name="right_joint" type="revolute">
        <parent>world</parent>
        <child>right</child>
        <axis>
          <xyz>0 0 1</xyz>
          <limit>
            <lower>0</lower>
            <upper>1.57</upper>
          </limit>
        </axis>
        <pose>0.47508285335173855 0 0 0 0 0</pose>
      </joint>
      <link name="left">
        <pose>-0.47508285335173855 0 1.11 0 0 0</pose>
        <visual name="left_visual">
          <geometry>
            <box>
              <size>0.9401657067034771 0.03 2.2</size>
            </box>
          </geometry>
          <material>
            <ambient>0.5 0.25 0 0.6</ambient>
            <diffuse>0.5 0.25 0 0.6</diffuse>
            <pbr>
              <metal>
                <metalness>0.0</metalness>
              </metal>
            </pbr>
          </material>
        </visual>
        <collision name="left_collision">
          <geometry>
            <box>
              <size>0.9401657067034771 0.03 2.2</size>
            </box>
          </geometry>
          <surface>
            <contact>
              <collide_bitmask>0x02</collide_bitmask>
            </contact>
          </surface>
        </collision>
        <inertial>
          <mass>50.0</mass>
          <inertia>
            <ixx>20.17041666666667</ixx>
            <iyy>23.849631483588542</iyy>
            <izz>3.686714816921869</izz>
          </inertia>
        </inertial>
      </link>
      <joint name="left_joint" type="revolute">
        <parent>world</parent>
        <child>left</child>
        <axis>
          <xyz>0 0 1</xyz>
          <limit>
            <lower>-1.57</lower>
            <upper>0</upper>
          </limit>
        </axis>
        <pose>-0.47508285335173855 0 0 0 0 0</pose>
      </joint>
    </model>
    <include>
      <name>kioto_L1</name>
      <uri>model://kioto_L1</uri>
      <pose>0 0 0.0 0 0 0</pose>
    </include>
    <include>
      <name>OpenRobotics/AdjTable_32</name>
      <uri>https://fuel.gazebosim.org/1.0/OpenRobotics/models/AdjTable</uri>
      <pose>18.618244214511726 -28.04577953910406 6.0 0 0 0.0</pose>
      <static>True</static>
    </include>
    <include>
      <name>OpenRobotics/AdjTable_33</name>
      <uri>https://fuel.gazebosim.org/1.0/OpenRobotics/models/AdjTable</uri>
      <pose>22.387410041985433 -28.03686808128135 6.0 0 0 0.0</pose>
      <static>True</static>
    </include>
    <include>
      <name>OpenRobotics/AdjTable_34</name>
      <uri>https://fuel.gazebosim.org/1.0/OpenRobotics/models/AdjTable</uri>
      <pose>25.662865872819996 -28.012723362223255 6.0 0 0 0.0</pose>
      <static>True</static>
    </include>
    <include>
      <name>OpenRobotics/OfficeChairGrey_61</name>
      <uri>https://fuel.gazebosim.org/1.0/OpenRobotics/models/OfficeChairGrey</uri>
      <pose>18.183943936690625 -28.62098748335256 6.0 0 0 -3.1416</pose>
      <static>True</static>
    </include>
    <include>
      <name>OpenRobotics/OfficeChairGrey_62</name>
      <uri>https://fuel.gazebosim.org/1.0/OpenRobotics/models/OfficeChairGrey</uri>
      <pose>19.043556868203947 -28.630584437930857 6.0 0 0 -3.1416</pose>
      <static>True</static>
    </include>
    <include>
      <name>OpenRobotics/OfficeChairGrey_63</name>
      <uri>https://fuel.gazebosim.org/1.0/OpenRobotics/models/OfficeChairGrey</uri>
      <pose>21.91258928927818 -28.64046066896514 6.0 0 0 -3.1416</pose>
      <static>True</static>
    </include>
    <include>
      <name>OpenRobotics/OfficeChairGrey_64</name>
      <uri>https://fuel.gazebosim.org/1.0/OpenRobotics/models/OfficeChairGrey</uri>
      <pose>22.91856847249492 -28.648508908651173 6.0 0 0 -3.1416</pose>
      <static>True</static>
    </include>
    <include>
      <name>OpenRobotics/OfficeChairGrey_65</name>
      <uri>https://fuel.gazebosim.org/1.0/OpenRobotics/models/OfficeChairGrey</uri>
      <pose>25.244382797914977 -28.61631594990704 6.0 0 0 -3.1416</pose>
      <static>True</static>
    </include>
    <include>
      <name>OpenRobotics/OfficeChairGrey_66</name>
      <uri>https://fuel.gazebosim.org/1.0/OpenRobotics/models/OfficeChairGrey</uri>
      <pose>26.12159014615518 -28.61631594990704 6.0 0 0 -3.1416</pose>
      <static>True</static>
    </include>
    <include>
      <name>kioto_L2</name>
      <uri>model://kioto_L2</uri>
      <pose>0 0 6.0 0 0 0</pose>
    </include>
    <model name="ShaftDoor_lift_L1_door">
      <pose>14.886878955483498 -29.32402787813475 0.0 0 0 1.57</pose>
      <link name="right_door">
        <pose>0.25 0 1.25 0 0 0</pose>
        <visual name="right_door_visual">
          <geometry>
            <box>
              <size>0.5 0.03 2.5</size>
            </box>
          </geometry>
          <material>
            <ambient>0.5 0.5 0.5 1</ambient>
            <diffuse>0.7 0.7 0.7 1</diffuse>
            <specular>0.6 0.6 0.6 1</specular>
            <emissive>0.1 0.1 0.1 1</emissive>
          </material>
        </visual>
        <collision name="right_door_collision">
          <geometry>
            <box>
              <size>0.5 0.03 2.5</size>
            </box>
          </geometry>
          <surface>
            <contact>
              <collide_bitmask>0x02</collide_bitmask>
            </contact>
          </surface>
        </collision>
      </link>
      <link name="left_door">
        <pose>-0.25 0 1.25 0 0 0</pose>
        <visual name="left_door_visual">
          <geometry>
            <box>
              <size>0.5 0.03 2.5</size>
            </box>
          </geometry>
          <material>
            <ambient>0.5 0.5 0.5 1</ambient>
            <diffuse>0.7 0.7 0.7 1</diffuse>
            <specular>0.6 0.6 0.6 1</specular>
            <emissive>0.1 0.1 0.1 1</emissive>
          </material>
        </visual>
        <collision name="left_door_collision">
          <geometry>
            <box>
              <size>0.5 0.03 2.5</size>
            </box>
          </geometry>
          <surface>
            <contact>
              <collide_bitmask>0x02</collide_bitmask>
            </contact>
          </surface>
        </collision>
      </link>
      <joint name="right_joint" type="prismatic">
        <parent>world</parent>
        <child>right_door</child>
        <axis>
          <xyz>1 0 0</xyz>
          <limit>
            <lower>0</lower>
            <upper>0.5</upper>
          </limit>
        </axis>
      </joint>
      <joint name="left_joint" type="prismatic">
        <parent>world</parent>
        <child>left_door</child>
        <axis>
          <xyz>1 0 0</xyz>
          <limit>
            <lower>-0.5</lower>
            <upper>0</upper>
          </limit>
        </axis>
      </joint>
      <link name="ramp">
        <pose>0 0 -0.025 0 0 0</pose>
        <visual name="ramp_visual">
          <geometry>
            <box>
              <size>1.0 0.1 0.05</size>
            </box>
          </geometry>
          <material>
            <ambient>0.5 0.5 0.5 1</ambient>
            <diffuse>0.7 0.7 0.7 1</diffuse>
            <specular>0.6 0.6 0.6 1</specular>
            <emissive>0.1 0.1 0.1 1</emissive>
          </material>
        </visual>
        <collision name="ramp_collision">
          <geometry>
            <box>
              <size>1.0 0.1 0.05</size>
            </box>
          </geometry>
          <surface>
            <contact>
              <collide_bitmask>0x02</collide_bitmask>
            </contact>
          </surface>
        </collision>
      </link>
      <joint name="ramp_joint" type="fixed">
        <parent>world</parent>
        <child>ramp</child>
      </joint>
      <plugin name="register_component" filename="libregister_component.so">
        <component name="Door">
          <v_max_door>0.3</v_max_door>
          <a_max_door>0.2</a_max_door>
          <a_nom_door>0.1</a_nom_door>
          <dx_min_door>0.0001</dx_min_door>
          <f_max_door>35.0</f_max_door>
          <door left_joint_name="left_joint" name="ShaftDoor_lift_L1_door" right_joint_name="right_joint" type="DoubleSlidingDoor" />
        </component>
      </plugin>
    </model>
    <model name="ShaftDoor_lift_L2_door">
      <pose>14.886878955483498 -29.32402787813475 6.0 0 0 1.57</pose>
      <link name="right_door">
        <pose>0.25 0 1.25 0 0 0</pose>
        <visual name="right_door_visual">
          <geometry>
            <box>
              <size>0.5 0.03 2.5</size>
            </box>
          </geometry>
          <material>
            <ambient>0.5 0.5 0.5 1</ambient>
            <diffuse>0.7 0.7 0.7 1</diffuse>
            <specular>0.6 0.6 0.6 1</specular>
            <emissive>0.1 0.1 0.1 1</emissive>
          </material>
        </visual>
        <collision name="right_door_collision">
          <geometry>
            <box>
              <size>0.5 0.03 2.5</size>
            </box>
          </geometry>
          <surface>
            <contact>
              <collide_bitmask>0x02</collide_bitmask>
            </contact>
          </surface>
        </collision>
      </link>
      <link name="left_door">
        <pose>-0.25 0 1.25 0 0 0</pose>
        <visual name="left_door_visual">
          <geometry>
            <box>
              <size>0.5 0.03 2.5</size>
            </box>
          </geometry>
          <material>
            <ambient>0.5 0.5 0.5 1</ambient>
            <diffuse>0.7 0.7 0.7 1</diffuse>
            <specular>0.6 0.6 0.6 1</specular>
            <emissive>0.1 0.1 0.1 1</emissive>
          </material>
        </visual>
        <collision name="left_door_collision">
          <geometry>
            <box>
              <size>0.5 0.03 2.5</size>
            </box>
          </geometry>
          <surface>
            <contact>
              <collide_bitmask>0x02</collide_bitmask>
            </contact>
          </surface>
        </collision>
      </link>
      <joint name="right_joint" type="prismatic">
        <parent>world</parent>
        <child>right_door</child>
        <axis>
          <xyz>1 0 0</xyz>
          <limit>
            <lower>0</lower>
            <upper>0.5</upper>
          </limit>
        </axis>
      </joint>
      <joint name="left_joint" type="prismatic">
        <parent>world</parent>
        <child>left_door</child>
        <axis>
          <xyz>1 0 0</xyz>
          <limit>
            <lower>-0.5</lower>
            <upper>0</upper>
          </limit>
        </axis>
      </joint>
      <link name="ramp">
        <pose>0 0 -0.025 0 0 0</pose>
        <visual name="ramp_visual">
          <geometry>
            <box>
              <size>1.0 0.1 0.05</size>
            </box>
          </geometry>
          <material>
            <ambient>0.5 0.5 0.5 1</ambient>
            <diffuse>0.7 0.7 0.7 1</diffuse>
            <specular>0.6 0.6 0.6 1</specular>
            <emissive>0.1 0.1 0.1 1</emissive>
          </material>
        </visual>
        <collision name="ramp_collision">
          <geometry>
            <box>
              <size>1.0 0.1 0.05</size>
            </box>
          </geometry>
          <surface>
            <contact>
              <collide_bitmask>0x02</collide_bitmask>
            </contact>
          </surface>
        </collision>
      </link>
      <joint name="ramp_joint" type="fixed">
        <parent>world</parent>
        <child>ramp</child>
      </joint>
      <plugin name="register_component" filename="libregister_component.so">
        <component name="Door">
          <v_max_door>0.3</v_max_door>
          <a_max_door>0.2</a_max_door>
          <a_nom_door>0.1</a_nom_door>
          <dx_min_door>0.0001</dx_min_door>
          <f_max_door>35.0</f_max_door>
          <door left_joint_name="left_joint" name="ShaftDoor_lift_L2_door" right_joint_name="right_joint" type="DoubleSlidingDoor" />
        </component>
      </plugin>
    </model>
    <model name="lift">
      <link name="platform">
        <inertial>
          <mass>1200</mass>
          <inertia>
            <ixx>400.25000000000006</ixx>
            <iyy>400.25000000000006</iyy>
            <izz>800.0</izz>
          </inertia>
        </inertial>
        <visual name="floor_visual">
          <pose>0 0 -0.025 0 0 0</pose>
          <geometry>
            <box>
              <size>2.0 2.0 0.05</size>
            </box>
          </geometry>
          <material>
            <ambient>0.5 0.5 0.5 1</ambient>
            <diffuse>0.7 0.7 0.7 1</diffuse>
            <specular>0.6 0.6 0.6 1</specular>
            <emissive>0.1 0.1 0.1 1</emissive>
          </material>
        </visual>
        <collision name="floor_collision">
          <pose>0 0 -0.025 0 0 0</pose>
          <geometry>
            <box>
              <size>2.0 2.0 0.05</size>
            </box>
          </geometry>
          <surface>
            <contact>
              <collide_bitmask>0x01</collide_bitmask>
            </contact>
          </surface>
        </collision>
        <visual name="frontwall1_visual">
          <pose>0.0 0.975 1.25 0 0 0</pose>
          <geometry>
            <box>
              <size>2.0 0.05 2.5</size>
            </box>
          </geometry>
          <material>
            <ambient>0.5 0.5 0.5 1</ambient>
            <diffuse>0.7 0.7 0.7 1</diffuse>
            <specular>0.6 0.6 0.6 1</specular>
            <emissive>0.1 0.1 0.1 1</emissive>
          </material>
        </visual>
        <collision name="frontwall1_collision">
          <pose>0.0 0.975 1.25 0 0 0</pose>
          <geometry>
            <box>
              <size>2.0 0.05 2.5</size>
            </box>
          </geometry>
          <surface>
            <contact>
              <collide_bitmask>0x01</collide_bitmask>
            </contact>
          </surface>
        </collision>
        <visual name="backwall1_visual">
          <pose>0.0 -0.975 1.25 0 0 0</pose>
          <geometry>
            <box>
              <size>2.0 0.05 2.5</size>
            </box>
          </geometry>
          <material>
            <ambient>0.5 0.5 0.5 1</ambient>
            <diffuse>0.7 0.7 0.7 1</diffuse>
            <specular>0.6 0.6 0.6 1</specular>
            <emissive>0.1 0.1 0.1 1</emissive>
          </material>
        </visual>
        <collision name="backwall1_collision">
          <pose>0.0 -0.975 1.25 0 0 0</pose>
          <geometry>
            <box>
              <size>2.0 0.05 2.5</size>
            </box>
          </geometry>
          <surface>
            <contact>
              <collide_bitmask>0x01</collide_bitmask>
            </contact>
          </surface>
        </collision>
        <visual name="leftwall1_visual">
          <pose>-0.975 0.0 1.25 0 0 1.5707963267948966</pose>
          <geometry>
            <box>
              <size>1.9 0.05 2.5</size>
            </box>
          </geometry>
          <material>
            <ambient>0.5 0.5 0.5 1</ambient>
            <diffuse>0.7 0.7 0.7 1</diffuse>
            <specular>0.6 0.6 0.6 1</specular>
            <emissive>0.1 0.1 0.1 1</emissive>
          </material>
        </visual>
        <collision name="leftwall1_collision">
          <pose>-0.975 0.0 1.25 0 0 1.5707963267948966</pose>
          <geometry>
            <box>
              <size>1.9 0.05 2.5</size>
            </box>
          </geometry>
          <surface>
            <contact>
              <collide_bitmask>0x01</collide_bitmask>
            </contact>
          </surface>
        </collision>
        <visual name="rightwall1_visual">
          <pose>0.975 -0.725 1.25 0 0 1.5707963267948966</pose>
          <geometry>
            <box>
              <size>0.44999999999999996 0.05 2.5</size>
            </box>
          </geometry>
          <material>
            <ambient>0.5 0.5 0.5 1</ambient>
            <diffuse>0.7 0.7 0.7 1</diffuse>
            <specular>0.6 0.6 0.6 1</specular>
            <emissive>0.1 0.1 0.1 1</emissive>
          </material>
        </visual>
        <collision name="rightwall1_collision">
          <pose>0.975 -0.725 1.25 0 0 1.5707963267948966</pose>
          <geometry>
            <box>
              <size>0.44999999999999996 0.05 2.5</size>
            </box>
          </geometry>
          <surface>
            <contact>
              <collide_bitmask>0x01</collide_bitmask>
            </contact>
          </surface>
        </collision>
        <visual name="rightwall2_visual">
          <pose>0.975 0.725 1.25 0 0 1.5707963267948966</pose>
          <geometry>
            <box>
              <size>0.44999999999999996 0.05 2.5</size>
            </box>
          </geometry>
          <material>
            <ambient>0.5 0.5 0.5 1</ambient>
            <diffuse>0.7 0.7 0.7 1</diffuse>
            <specular>0.6 0.6 0.6 1</specular>
            <emissive>0.1 0.1 0.1 1</emissive>
          </material>
        </visual>
        <collision name="rightwall2_collision">
          <pose>0.975 0.725 1.25 0 0 1.5707963267948966</pose>
          <geometry>
            <box>
              <size>0.44999999999999996 0.05 2.5</size>
            </box>
          </geometry>
          <surface>
            <contact>
              <collide_bitmask>0x01</collide_bitmask>
            </contact>
          </surface>
        </collision>
      </link>
      <joint name="cabin_joint" type="prismatic">
        <parent>world</parent>
        <child>platform</child>
        <axis>
          <xyz>0 0 1</xyz>
        </axis>
      </joint>
      <model name="CabinDoor_lift_door">
        <pose>0.975 0.0 0 0 0 1.57</pose>
        <link name="right_door">
          <pose>0.25 0 1.25 0 0 0</pose>
          <visual name="right_door_visual">
            <geometry>
              <box>
                <size>0.5 0.03 2.5</size>
              </box>
            </geometry>
            <material>
              <ambient>0.5 0.5 0.5 1</ambient>
              <diffuse>0.7 0.7 0.7 1</diffuse>
              <specular>0.6 0.6 0.6 1</specular>
              <emissive>0.1 0.1 0.1 1</emissive>
            </material>
          </visual>
          <collision name="right_door_collision">
            <geometry>
              <box>
                <size>0.5 0.03 2.5</size>
              </box>
            </geometry>
            <surface>
              <contact>
                <collide_bitmask>0x02</collide_bitmask>
              </contact>
            </surface>
          </collision>
        </link>
        <link name="left_door">
          <pose>-0.25 0 1.25 0 0 0</pose>
          <visual name="left_door_visual">
            <geometry>
              <box>
                <size>0.5 0.03 2.5</size>
              </box>
            </geometry>
            <material>
              <ambient>0.5 0.5 0.5 1</ambient>
              <diffuse>0.7 0.7 0.7 1</diffuse>
              <specular>0.6 0.6 0.6 1</specular>
              <emissive>0.1 0.1 0.1 1</emissive>
            </material>
          </visual>
          <collision name="left_door_collision">
            <geometry>
              <box>
                <size>0.5 0.03 2.5</size>
              </box>
            </geometry>
            <surface>
              <contact>
                <collide_bitmask>0x02</collide_bitmask>
              </contact>
            </surface>
          </collision>
        </link>
        <plugin name="register_component" filename="libregister_component.so">
          <component name="Door">
            <v_max_door>0.3</v_max_door>
            <a_max_door>0.2</a_max_door>
            <a_nom_door>0.1</a_nom_door>
            <dx_min_door>0.0001</dx_min_door>
            <f_max_door>35.0</f_max_door>
            <door left_joint_name="CabinDoor_lift_door_left_joint" name="CabinDoor_lift_door" right_joint_name="CabinDoor_lift_door_right_joint" type="DoubleSlidingDoor" />
          </component>
        </plugin>
      </model>
      <joint name="CabinDoor_lift_door_right_joint" type="prismatic">
        <parent>platform</parent>
        <child>CabinDoor_lift_door::right_door</child>
        <axis>
          <xyz>1 0 0</xyz>
          <limit>
            <lower>0</lower>
            <upper>0.5</upper>
          </limit>
        </axis>
      </joint>
      <joint name="CabinDoor_lift_door_left_joint" type="prismatic">
        <parent>platform</parent>
        <child>CabinDoor_lift_door::left_door</child>
        <axis>
          <xyz>1 0 0</xyz>
          <limit>
            <lower>-0.5</lower>
            <upper>0</upper>
          </limit>
        </axis>
      </joint>
      <plugin name="register_component" filename="libregister_component.so">
        <component name="Lift">
          <lift_name>lift</lift_name>
          <floor name="L1" elevation="0.0">
            <door_pair cabin_door="CabinDoor_lift_door" shaft_door="ShaftDoor_lift_L1_door" />
          </floor>
          <floor name="L2" elevation="6.0">
            <door_pair cabin_door="CabinDoor_lift_door" shaft_door="ShaftDoor_lift_L2_door" />
          </floor>
          <initial_floor>L1</initial_floor>
          <v_max_cabin>2.0</v_max_cabin>
          <a_max_cabin>1.2</a_max_cabin>
          <a_nom_cabin>1.0</a_nom_cabin>
          <dx_min_cabin>0.001</dx_min_cabin>
          <f_max_cabin>25323.0</f_max_cabin>
          <cabin_joint_name>cabin_joint</cabin_joint_name>
        </component>
      </plugin>
      <pose>13.836878955483497 -29.32402787813475 0 0 0 0.0</pose>
    </model>
    <plugin name="register_component" filename="libregister_component.so">
      <component name="Chargers">
        <rmf_charger name="charger_1" x="26.275446084632666" y="-7.794783607845279" z="0.0" />
        <rmf_charger name="charger_2" x="14.742115504396825" y="-7.8907785423969905" z="0.0" />
        <rmf_charger name="charger_3" x="22.63959668173739" y="-26.383145241566904" z="0.0" />
      </component>
    </plugin>
  </world>
</sdf>
